<robot name="car_total" xmlns:xacro="http://www.ros.org/wiki/xacro">

<!--`````````````````````````````````````````base_footprint`````````````````````````````````````` -->
  <link name="base_footprint">
    <visual>
      <geometry>
        <sphere radius="0.001" />
      </geometry>
    </visual>
  </link>


<!--`````````````````````````````````````````base_link`````````````````````````````````````` -->

  <link name="base_link">
    <visual> 
      <geometry>
        <box size="0.6 0.4 0.2" />
      </geometry>
      <origin rpy="0 0 0" xyz="0 0 0"/>
      <material name="gary">
        <color rgba="0.7 0.7 0.7 1.0" />
      </material>
    </visual>

    <collision>
      <origin rpy="0 0 0" xyz="0 0 0"/>
      <geometry>
        <box size="0.6 0.4 0.2" />
      </geometry>
    </collision>

    <inertial>
      <mass value="40" />
      <inertia ixx="1.333" ixy = "0" ixz = "0"
          iyy="1.733" iyz= "0"
          izz="0.6667" />
    </inertial>
  </link>

  <joint name="base_link2base_footprint" type="fixed">
      <parent link="base_footprint" />
      <child link="base_link"/>
      <origin xyz="0 0 0.15" />
  </joint>

  <gazebo reference="base_link">
    <material>Gazebo/Purple</material>
  </gazebo>



<!--`````````````````````````````````````````id_link`````````````````````````````````````` -->

  <link name="id_link">
    <visual> 
      <geometry>
        <mesh filename="package://car_gazebo/meshes/id_link.STL"/>
      </geometry>
      <origin rpy="1.5705 0 -1.5705" xyz="0 0 0"/>
      <material name="red">
        <color rgba="1.0 0 0 1.0" />
      </material>
    </visual>

    <collision>
      <origin rpy="1.5705 0 -1.5705" xyz="0 0 0"/>
      <geometry>
        <mesh filename="package://car_gazebo/meshes/id_link.STL"/>
      </geometry>
    </collision>

    <inertial>
      <mass value="4" />
      <inertia ixx="0.1333" ixy = "0" ixz = "0"
          iyy="0.1733" iyz= "0"
          izz="0.06667" />
    </inertial>
  </link>

  <joint name="id2base" type="fixed">
      <parent link="base_link" />
      <child link="id_link"/>
      <origin xyz="-0.3 0.2 -0.1" />
  </joint>

  <gazebo reference="id_link">
    <material>Gazebo/Red</material>
  </gazebo>


<!-- ```````````````````````````sup_link``````````````````````````` -->

  <link name="sup_link">

    <visual>
      <origin rpy="0 0 0" xyz="0 0 0"/>
      <geometry>
        <cylinder radius="0.025" length="0.18" />
      </geometry>
    </visual>
      <material name="black">
        <color rgba="0 0 0 1.0" />
      </material>
  </link>

  <joint name="sup2base" type="fixed">
    <parent link="base_link"/>
    <child link="sup_link"/>
    <origin rpy="0 0 0" xyz="-0.10 0 0.14"/>
  </joint>

  <gazebo reference="sup_link">
    <material>Gazebo/Black</material>
  </gazebo>


<!-- ```````````````````````````laser_link``````````````````````````` -->

  <link name="laser_link">

    <visual>
      <origin rpy="1.5705 0 0" xyz="0 0 0"/>
      <geometry>
        <mesh filename="package://car_gazebo/meshes/laser_link.STL"/>
      </geometry>
    </visual>
      <material name="green">
        <color rgba="0 1.0 0 1.0" />
      </material>
  </link>

  <joint name="laser2base" type="fixed">
    <parent link="base_link"/>
    <child link="laser_link"/>
    <origin rpy="0 0 0" xyz="-0.15 0.05 0.23"/>
  </joint>

  <gazebo reference="laser_link">
    <material>Gazebo/Green</material>
  </gazebo>


  <link name="laser_core">  <!-- the core is for sensor's center is not what i want, so use "core" to tiaozheng center. -->
    <visual>
      <origin rpy="0 0 0" xyz="0 0 0"/>
      <geometry>
        <sphere radius="0.001" />
      </geometry>
    </visual>
  </link>
  <joint name="laser2core" type="fixed">
    <parent link="laser_link"/>
    <child link="laser_core"/>
    <origin rpy="0 0 0" xyz="0.05 -0.05 0.05"/>
  </joint>

<!-- ```````````````````````````camera_link`````````````````````````````` -->

  <link name="camera_link">

    <visual>
      <origin rpy="0 0 0" xyz="0 0 0"/>
      <geometry>
        <box size="0.02 0.12 0.14" />      
      </geometry>
    </visual>
      <material name="blue">
        <color rgba="0 0 1.0 1.0" />
      </material>
  </link>

  <joint name="camera2base" type="fixed">
    <parent link="base_link"/>
    <child link="camera_link"/>
    <origin rpy="0 0 0" xyz="0.08 0 0.08"/>
  </joint>

  <gazebo reference="camera_link">
    <material>Gazebo/Blue</material>
  </gazebo>

  <link name="camera_core">  <!-- the core is for sensor's rpy&center is not what i want, so use "core" to tiaozheng rpy&center. -->
    <visual>
      <origin rpy="0 0 0" xyz="0 0 0"/>
      <geometry>
        <sphere radius="0.001" />
      </geometry>
    </visual>
  </link>
  <joint name="camera2core" type="fixed">
    <parent link="camera_link"/>
    <child link="camera_core"/>
    <origin rpy="0 0 0" xyz="0.3 0 0.05"/>
  </joint>
  
<!--``````````````````````````````````````````` f_l_w_link`````````````````````````````````````````` -->

  <link name="front_left_wheel_link">

    <visual>
      <origin rpy="1.5705 0 0" xyz="0 0 0"/>
      <geometry>
        <cylinder radius="0.05" length="0.06" />
      </geometry>
      <material name="black">
        <color rgba="0 0 0 1.0" />
      </material>
    </visual>

    <collision>
      <origin rpy="1.5705 0 0" xyz="0 0 0"/>
      <geometry>
        <cylinder radius="0.05" length="0.06" />
      </geometry>
    </collision>

    <inertial>
      <mass value="0.1" />
      <inertia ixx="0.0000925" ixy = "0" ixz = "0"
          iyy="0.0000925" iyz = "0"
          izz="0.000125" /> 
    </inertial>
  </link>



  <joint name="front_left_wheel" type="continuous">
    <parent link="base_link"/>
    <child link="front_left_wheel_link"/>
    <origin xyz="0.25 0.23 -0.10"/>
    <axis xyz="0 1 0"/>
  </joint>

  <gazebo reference="front_left_wheel_link">
    <material>Gazebo/Black</material>
  </gazebo>

<!-- ```````````````````````````````r_l_w_link````````````````````````````` -->

  <link name="rear_left_wheel_link">

    <visual>
      <origin rpy="1.5705 0 0" xyz="0 0 0"/>
      <geometry>
        <cylinder radius="0.05" length="0.06" />
      </geometry>
      <material name="black">
        <color rgba="0 0 0 1.0" />
      </material>
    </visual>

    <collision>
      <origin rpy="1.5705 0 0" xyz="0 0 0"/>
      <geometry>
        <cylinder radius="0.05" length="0.06" />
      </geometry>
    </collision>

    <inertial>
      <mass value="0.1" />
      <inertia ixx="0.0000925" ixy = "0" ixz = "0"
          iyy="0.0000925" iyz = "0"
          izz="0.000125" /> 
    </inertial>
  </link>

  <joint name="rear_left_wheel" type="continuous">
    <parent link="base_link"/>
    <child link="rear_left_wheel_link"/>
    <origin xyz="-0.25 0.23 -0.10"/>
    <axis xyz="0 1 0"/>
  </joint>

  <gazebo reference="rear_left_wheel_link">
    <material>Gazebo/Black</material>
  </gazebo>

<!-- ````````````````````````````````f_r_w_link``````````````````````````````` -->
  
  <link name="front_right_wheel_link">

    <visual>
      <origin rpy="1.5705 0 0" xyz="0 0 0"/>
      <geometry>
        <cylinder radius="0.05" length="0.06" />
      </geometry>
      <material name="black">
        <color rgba="0 0 0 1.0" />
      </material>
    </visual>

    <collision>
      <origin rpy="1.5705 0 0" xyz="0 0 0"/>
      <geometry>
        <cylinder radius="0.05" length="0.06" />
      </geometry>
    </collision>

    <inertial>
      <mass value="0.1" />
      <inertia ixx="0.0000925" ixy = "0" ixz = "0"
          iyy="0.0000925" iyz = "0"
          izz="0.000125" /> 
    </inertial>

  </link>

  <joint name="front_right_wheel" type="continuous">
    <parent link="base_link"/>
    <child link="front_right_wheel_link"/>
    <origin xyz="0.25 -0.23 -0.10"/>
    <axis xyz="0 1 0"/>
  </joint>

  <gazebo reference="front_right_wheel_link">
    <material>Gazebo/Black</material>
  </gazebo>

<!-- ````````````````````````````````r_r_w_link````````````````````````````` -->

  <link name="rear_right_wheel_link">

    <visual>
      <origin rpy="1.5705 0 0" xyz="0 0 0"/>
      <geometry>
        <cylinder radius="0.05" length="0.06" />
      </geometry>
      <material name="black">
        <color rgba="0 0 0 1.0" />
      </material>
    </visual>

    <collision>
      <origin rpy="1.5705 0 0" xyz="0 0 0"/>
      <geometry>
        <cylinder radius="0.05" length="0.06" />
      </geometry>
    </collision>

    <inertial>
      <mass value="0.1" />
      <inertia ixx="0.0000925" ixy = "0" ixz = "0"
          iyy="0.0000925" iyz = "0"
          izz="0.000125" /> 
    </inertial>

  </link>

  <joint name="rear_right_wheel" type="continuous">
    <parent link="base_link"/>
    <child link="rear_right_wheel_link"/>
    <origin xyz="-0.25 -0.23 -0.10"/>
    <axis xyz="0 1 0"/>
  </joint>

  <gazebo reference="rear_right_wheel_link">
    <material>Gazebo/Black</material>
  </gazebo>

<!-- `````````````````````````````````````move`````````````````````````````````````` -->

  <transmission name="front_right_wheel_trans" type="SimpleTransmission">
    <type>transmission_interface/SimpleTransmission</type>
    <actuator name="front_right_wheel_motor">
      <mechanicalReduction>1</mechanicalReduction>
    </actuator>
    <joint name="front_right_wheel">
      <hardwareInterface>hardware_interface/VelocityJointInterface</hardwareInterface>
    </joint>
  </transmission>

  <transmission name="front_left_wheel_trans" type="SimpleTransmission">
    <type>transmission_interface/SimpleTransmission</type>
    <actuator name="front_left_wheel_motor">
      <mechanicalReduction>1</mechanicalReduction>
    </actuator>
    <joint name="front_left_wheel">
      <hardwareInterface>hardware_interface/VelocityJointInterface</hardwareInterface>
    </joint>
  </transmission>

  <transmission name="rear_left_wheel_trans" type="SimpleTransmission">
    <type>transmission_interface/SimpleTransmission</type>
    <actuator name="rear_left_wheel_motor">
      <mechanicalReduction>1</mechanicalReduction>
    </actuator>
    <joint name="rear_left_wheel">
      <hardwareInterface>hardware_interface/VelocityJointInterface</hardwareInterface>
    </joint>
  </transmission>

  <transmission name="rear_right_wheel_trans" type="SimpleTransmission">
    <type>transmission_interface/SimpleTransmission</type>
    <actuator name="rear_right_wheel_motor">
      <mechanicalReduction>1</mechanicalReduction>
    </actuator>
    <joint name="rear_right_wheel">
      <hardwareInterface>hardware_interface/VelocityJointInterface</hardwareInterface>
    </joint>
  </transmission>


  <!-- Controller configurations -->
  <gazebo>
    <plugin filename="libgazebo_ros_control.so" name="gazebo_ros_control">
      <robotNamespace>/</robotNamespace>
    </plugin>
  </gazebo>


  <!-- kp spring constant, kd damping constant -->
  <gazebo>
    <mu1 value="1.0"/>
    <mu2 value="0.9"/>
    <kp value="10000000.0"/>
    <kd value="1.0"/>
    <fdir1 value="1 0 0"/>
    <minDepth value="0.001"/>
    <maxContacts value="64"/>
  </gazebo>


  <gazebo>
        <plugin name="skid_steer_drive_controller" filename="libgazebo_ros_skid_steer_drive.so">
            <updateRate>100.0</updateRate>
            <robotNamespace></robotNamespace>
            <leftFrontJoint>front_left_wheel</leftFrontJoint>
            <rightFrontJoint>front_right_wheel</rightFrontJoint>
            <leftRearJoint>rear_left_wheel</leftRearJoint>
            <rightRearJoint>rear_right_wheel</rightRearJoint>
            <wheelSeparation>4</wheelSeparation>
            <wheelDiameter>0.32918</wheelDiameter>
            <robotBaseFrame>base_footprint</robotBaseFrame><!-- base_link is the origin, reset!!!-->
            <torque>5000</torque> <!-- 1000 is the origin-->
            <commandTopic>cmd_vel</commandTopic>
            <broadcastTF>true</broadcastTF>
            <odometryTopic>odom</odometryTopic>
            <odometryFrame>odom</odometryFrame>
            <covariance_x>0.000100</covariance_x>
            <covariance_y>0.000100</covariance_y>
            <covariance_yaw>0.010000</covariance_yaw>
        </plugin>
    </gazebo>
    
  <gazebo>
        <plugin name="object_controller" filename="libgazebo_ros_planar_move.so">
            <commandTopic>cmd_vel</commandTopic>
            <odometryTopic>odom</odometryTopic>
            <odometryFrame>odom</odometryFrame>
            <odometryRate>20.0</odometryRate>
            <robotBaseFrame>base_footprint</robotBaseFrame>
        </plugin>
    </gazebo>

<!-- ``````````````````````````````````````````laser``````````````````````````````````````` -->

      <xacro:include filename = "gazebo/laser.xacro"  />

<!-- `````````````````````````````````````````kinect````````````````````````````````````````` -->

    <xacro:include filename = "gazebo/kinect.xacro"  />
  

</robot>